<?xml version="1.0" encoding="utf-8"?>
<!-- This URDF was automatically created by SolidWorks to URDF Exporter! Originally created by Stephen Brawner (brawner@gmail.com) 
     Commit Version: 1.6.0-4-g7f85cfe  Build Version: 1.6.7995.38578
     For more information, please see http://wiki.ros.org/sw_urdf_exporter -->
<robot
  name="spiderbot">
  <link
    name="base_link">
    <inertial>
      <origin
        xyz="8.8431E-07 -2.8309E-06 0.075"
        rpy="0 0 0" />
      <mass
        value="1.0797" />
      <inertia
        ixx="0.0036422"
        ixy="6.9366E-08"
        ixz="-2.9718E-09"
        iyy="0.0036423"
        iyz="1.993E-08"
        izz="0.0072588" />
    </inertial>
    <visual>
      <origin
        xyz="0 0 0"
        rpy="0 0 0" />
      <geometry>
        <mesh
          filename="package://spiderbot/meshes/base_link.STL" />
      </geometry>
      <material
        name="">
        <color
          rgba="1 0 0 1" />
      </material>
    </visual>
    <collision>
      <origin
        xyz="0 0 0"
        rpy="0 0 0" />
      <geometry>
        <mesh
          filename="package://spiderbot/meshes/base_link.STL" />
      </geometry>
    </collision>
  </link>
  <link
    name="front_right_link0">
    <inertial>
      <origin
        xyz="-1.4232E-08 -0.03892 0.039146"
        rpy="0 0 0" />
      <mass
        value="0.071655" />
      <inertia
        ixx="0.00019551"
        ixy="-3.7597E-12"
        ixz="-1.2218E-11"
        iyy="0.00011898"
        iyz="8.9125E-05"
        izz="8.1036E-05" />
    </inertial>
    <visual>
      <origin
        xyz="0 0 0"
        rpy="0 0 0" />
      <geometry>
        <mesh
          filename="package://spiderbot/meshes/front_right_link0.STL" />
      </geometry>
      <material
        name="">
        <color
          rgba="0 0 1 1" />
      </material>
    </visual>
    <collision>
      <origin
        xyz="0 0 0"
        rpy="0 0 0" />
      <geometry>
        <mesh
          filename="package://spiderbot/meshes/front_right_link0.STL" />
      </geometry>
    </collision>
  </link>
  <joint
    name="joint_front_right_link0"
    type="continuous">
    <origin
      xyz="0.1 -0.1 0.075"
      rpy="0 0 0.7854" />
    <parent
      link="base_link" />
    <child
      link="front_right_link0" />
    <axis
      xyz="0 0 1" />
  </joint>
  <link
    name="front_right_link1">
    <inertial>
      <origin
        xyz="-0.054513 -0.069963 -1.093E-08"
        rpy="0 0 0" />
      <mass
        value="0.069773" />
      <inertia
        ixx="0.00026729"
        ixy="-0.00017233"
        ixz="3.0936E-11"
        iyy="0.0001253"
        iyz="3.4186E-11"
        izz="0.00039089" />
    </inertial>
    <visual>
      <origin
        xyz="0 0 0"
        rpy="0 0 0" />
      <geometry>
        <mesh
          filename="package://spiderbot/meshes/front_right_link1.STL" />
      </geometry>
      <material
        name="">
        <color
          rgba="0 1 0 1" />
      </material>
    </visual>
    <collision>
      <origin
        xyz="0 0 0"
        rpy="0 0 0" />
      <geometry>
        <mesh
          filename="package://spiderbot/meshes/front_right_link1.STL" />
      </geometry>
    </collision>
  </link>
  <joint
    name="joint_front_right_link1"
    type="continuous">
    <origin
      xyz="0 -0.1 0.099999999999999"
      rpy="1.5707963267949 0 1.57079632679489" />
    <parent
      link="front_right_link0" />
    <child
      link="front_right_link1" />
    <axis
      xyz="0 0 1" />
  </joint>
  <link
    name="front_left_link0">
    <inertial>
      <origin
        xyz="-1.4232E-08 -0.03892 0.039146"
        rpy="0 0 0" />
      <mass
        value="0.071655" />
      <inertia
        ixx="0.00019551"
        ixy="-3.7597E-12"
        ixz="-1.2218E-11"
        iyy="0.00011898"
        iyz="8.9125E-05"
        izz="8.1036E-05" />
    </inertial>
    <visual>
      <origin
        xyz="0 0 0"
        rpy="0 0 0" />
      <geometry>
        <mesh
          filename="package://spiderbot/meshes/front_left_link0.STL" />
      </geometry>
      <material
        name="">
        <color
          rgba="0 0 1 1" />
      </material>
    </visual>
    <collision>
      <origin
        xyz="0 0 0"
        rpy="0 0 0" />
      <geometry>
        <mesh
          filename="package://spiderbot/meshes/front_left_link0.STL" />
      </geometry>
    </collision>
  </link>
  <joint
    name="joint_front_left_link0"
    type="continuous">
    <origin
      xyz="0.1 0.1 0.075"
      rpy="0 0 2.35619449019234" />
    <parent
      link="base_link" />
    <child
      link="front_left_link0" />
    <axis
      xyz="0 0 1" />
  </joint>
  <link
    name="front_left_link1">
    <inertial>
      <origin
        xyz="-0.054513 -0.069963 -1.093E-08"
        rpy="0 0 0" />
      <mass
        value="0.069773" />
      <inertia
        ixx="0.00026729"
        ixy="-0.00017233"
        ixz="3.0936E-11"
        iyy="0.0001253"
        iyz="3.4186E-11"
        izz="0.00039089" />
    </inertial>
    <visual>
      <origin
        xyz="0 0 0"
        rpy="0 0 0" />
      <geometry>
        <mesh
          filename="package://spiderbot/meshes/front_left_link1.STL" />
      </geometry>
      <material
        name="">
        <color
          rgba="0 1 0 1" />
      </material>
    </visual>
    <collision>
      <origin
        xyz="0 0 0"
        rpy="0 0 0" />
      <geometry>
        <mesh
          filename="package://spiderbot/meshes/front_left_link1.STL" />
      </geometry>
    </collision>
  </link>
  <joint
    name="joint_front_left_link1"
    type="continuous">
    <origin
      xyz="0 -0.1 0.0999999999999989"
      rpy="1.5707963267949 0 1.5707963267949" />
    <parent
      link="front_left_link0" />
    <child
      link="front_left_link1" />
    <axis
      xyz="0 0 1" />
  </joint>
  <link
    name="rear_left_link0">
    <inertial>
      <origin
        xyz="-1.4232E-08 -0.03892 0.039146"
        rpy="0 0 0" />
      <mass
        value="0.071655" />
      <inertia
        ixx="0.00019551"
        ixy="-3.7597E-12"
        ixz="-1.2218E-11"
        iyy="0.00011898"
        iyz="8.9125E-05"
        izz="8.1036E-05" />
    </inertial>
    <visual>
      <origin
        xyz="0 0 0"
        rpy="0 0 0" />
      <geometry>
        <mesh
          filename="package://spiderbot/meshes/rear_left_link0.STL" />
      </geometry>
      <material
        name="">
        <color
          rgba="0 0 1 1" />
      </material>
    </visual>
    <collision>
      <origin
        xyz="0 0 0"
        rpy="0 0 0" />
      <geometry>
        <mesh
          filename="package://spiderbot/meshes/rear_left_link0.STL" />
      </geometry>
    </collision>
  </link>
  <joint
    name="joint_rear_left_link0"
    type="continuous">
    <origin
      xyz="-0.1 0.0999999999999999 0.075"
      rpy="0 0 -2.35619449019234" />
    <parent
      link="base_link" />
    <child
      link="rear_left_link0" />
    <axis
      xyz="0 0 1" />
  </joint>
  <link
    name="rear_left_link1">
    <inertial>
      <origin
        xyz="-0.054513 -0.069963 -1.093E-08"
        rpy="0 0 0" />
      <mass
        value="0.069773" />
      <inertia
        ixx="0.00026729"
        ixy="-0.00017233"
        ixz="3.0936E-11"
        iyy="0.0001253"
        iyz="3.4186E-11"
        izz="0.00039089" />
    </inertial>
    <visual>
      <origin
        xyz="0 0 0"
        rpy="0 0 0" />
      <geometry>
        <mesh
          filename="package://spiderbot/meshes/rear_left_link1.STL" />
      </geometry>
      <material
        name="">
        <color
          rgba="0 1 0 1" />
      </material>
    </visual>
    <collision>
      <origin
        xyz="0 0 0"
        rpy="0 0 0" />
      <geometry>
        <mesh
          filename="package://spiderbot/meshes/rear_left_link1.STL" />
      </geometry>
    </collision>
  </link>
  <joint
    name="joint_rear_left_link1"
    type="continuous">
    <origin
      xyz="0 -0.1 0.0999999999999991"
      rpy="1.5707963267949 0 1.5707963267949" />
    <parent
      link="rear_left_link0" />
    <child
      link="rear_left_link1" />
    <axis
      xyz="0 0 1" />
  </joint>
  <link
    name="rear_right_link0">
    <inertial>
      <origin
        xyz="-1.4232E-08 -0.03892 0.039146"
        rpy="0 0 0" />
      <mass
        value="0.071655" />
      <inertia
        ixx="0.00019551"
        ixy="-3.7597E-12"
        ixz="-1.2218E-11"
        iyy="0.00011898"
        iyz="8.9125E-05"
        izz="8.1036E-05" />
    </inertial>
    <visual>
      <origin
        xyz="0 0 0"
        rpy="0 0 0" />
      <geometry>
        <mesh
          filename="package://spiderbot/meshes/rear_right_link0.STL" />
      </geometry>
      <material
        name="">
        <color
          rgba="0 0 1 1" />
      </material>
    </visual>
    <collision>
      <origin
        xyz="0 0 0"
        rpy="0 0 0" />
      <geometry>
        <mesh
          filename="package://spiderbot/meshes/rear_right_link0.STL" />
      </geometry>
    </collision>
  </link>
  <joint
    name="joint_rear_right_link0"
    type="continuous">
    <origin
      xyz="-0.1 -0.1 0.075"
      rpy="0 0 -0.7854" />
    <parent
      link="base_link" />
    <child
      link="rear_right_link0" />
    <axis
      xyz="0 0 1" />
  </joint>
  <link
    name="rear_right_link1">
    <inertial>
      <origin
        xyz="-0.054513 -0.069963 -1.093E-08"
        rpy="0 0 0" />
      <mass
        value="0.069773" />
      <inertia
        ixx="0.00026729"
        ixy="-0.00017233"
        ixz="3.0936E-11"
        iyy="0.0001253"
        iyz="3.4186E-11"
        izz="0.00039089" />
    </inertial>
    <visual>
      <origin
        xyz="0 0 0"
        rpy="0 0 0" />
      <geometry>
        <mesh
          filename="package://spiderbot/meshes/rear_right_link1.STL" />
      </geometry>
      <material
        name="">
        <color
          rgba="0 1 0 1" />
      </material>
    </visual>
    <collision>
      <origin
        xyz="0 0 0"
        rpy="0 0 0" />
      <geometry>
        <mesh
          filename="package://spiderbot/meshes/rear_right_link1.STL" />
      </geometry>
    </collision>
  </link>
  <joint
    name="joint_rear_right_link1"
    type="continuous">
    <origin
      xyz="0 -0.1 0.1"
      rpy="1.5708 0 1.5708" />
    <parent
      link="rear_right_link0" />
    <child
      link="rear_right_link1" />
    <axis
      xyz="0 0 1" />
  </joint>

    <!--Transmission Definitions -->
 <!--Transmission Front Right Links -->
 <transmission name="transmission_front_right_link0">
  <type>SimpleTransmission</type>
  <joint name="joint_front_right_link0">
    <hardwareInterface>hardware_interface/EffortJointInterface</hardwareInterface>
  </joint>
  <actuator name="motor_front_right_link0">
    <mechanicalReduction>1</mechanicalReduction>
    <hardwareInterface>VelocityJointInterface</hardwareInterface>
  </actuator>
</transmission>

<transmission name="transmission_front_right_link1">
  <type>SimpleTransmission</type>
  <joint name="joint_front_right_link1">
    <hardwareInterface>hardware_interface/EffortJointInterface</hardwareInterface>
  </joint>
  <actuator name="motor_front_right_link1">
    <mechanicalReduction>1</mechanicalReduction>
    <hardwareInterface>VelocityJointInterface</hardwareInterface>
  </actuator>
</transmission>

<!--Transmission Front Left Links -->
<transmission name="transmission_front_left_link0">
  <type>SimpleTransmission</type>
  <joint name="joint_front_left_link0">
    <hardwareInterface>hardware_interface/EffortJointInterface</hardwareInterface>
  </joint>
  <actuator name="motor_front_left_link0">
    <mechanicalReduction>1</mechanicalReduction>
    <hardwareInterface>VelocityJointInterface</hardwareInterface>
  </actuator>
</transmission>

<transmission name="transmission_front_left_link1">
  <type>SimpleTransmission</type>
  <joint name="joint_front_left_link1">
    <hardwareInterface>hardware_interface/EffortJointInterface</hardwareInterface>
  </joint>
  <actuator name="motor_front_left_link1">
    <mechanicalReduction>1</mechanicalReduction>
    <hardwareInterface>VelocityJointInterface</hardwareInterface>
  </actuator>
</transmission>

  <!--Transmission Rear Right Links -->
<transmission name="transmission_rear_right_link0">
  <type>SimpleTransmission</type>
  <joint name="joint_rear_right_link0">
    <hardwareInterface>hardware_interface/EffortJointInterface</hardwareInterface>
  </joint>
  <actuator name="motor_rear_right_link0">
    <mechanicalReduction>1</mechanicalReduction>
    <hardwareInterface>VelocityJointInterface</hardwareInterface>
  </actuator>
</transmission>

<transmission name="transmission_rear_right_link1">
  <type>SimpleTransmission</type>
  <joint name="joint_rear_right_link1">
    <hardwareInterface>hardware_interface/EffortJointInterface</hardwareInterface>
  </joint>
  <actuator name="motor_rear_right_link1">
    <mechanicalReduction>1</mechanicalReduction>
    <hardwareInterface>VelocityJointInterface</hardwareInterface>
  </actuator>
</transmission>

<!--Transmission Rear Left Links -->
<transmission name="transmission_rear_left_link0">
  <type>SimpleTransmission</type>
  <joint name="joint_rear_left_link0">
    <hardwareInterface>hardware_interface/EffortJointInterface</hardwareInterface>
  </joint>
  <actuator name="motor_rear_left_link0">
    <mechanicalReduction>1</mechanicalReduction>
    <hardwareInterface>VelocityJointInterface</hardwareInterface>
  </actuator>
</transmission>

<transmission name="transmission_rear_left_link1">
  <type>SimpleTransmission</type>
  <joint name="joint_rear_left_link1">
    <hardwareInterface>hardware_interface/EffortJointInterface</hardwareInterface>
  </joint>
  <actuator name="motor_rear_left_link1">
    <mechanicalReduction>1</mechanicalReduction>
    <hardwareInterface>VelocityJointInterface</hardwareInterface>
  </actuator>
</transmission>
</robot>