<?xml version="1.0" encoding="utf-8"?>
<!-- This URDF was automatically created by SolidWorks to URDF Exporter! Originally created by Stephen Brawner (brawner@gmail.com) 
     Commit Version: 1.5.1-0-g916b5db  Build Version: 1.5.7152.31018
     For more information, please see http://wiki.ros.org/sw_urdf_exporter -->
<robot name="spiderbotv8" xmlns:xacro="http://ros.org/wiki/xacro">
  <link name= "base_footprint"/>
  <joint name="base" type="fixed">
    <origin xyz="0.0 0.0 0.0" rpy="0 0 0"/>
    <parent link="base_footprint" />
    <child link="base_link" />
    <axis xyz="0 0 0" />
  </joint>
  <link name="base_link">
    <inertial>
      <origin
        xyz="6.52377531783468E-05 -0.0021170715917473 0.0364107331720625"
        rpy="0 0 0" />
      <mass value="0.0726541894616852" />
      <inertia
        ixx="3.02647463521448E-05"
        ixy="1.57081847985685E-09"
        ixz="3.15890627766527E-11"
        iyy="1.78058902607528E-05"
        iyz="-1.01459254458863E-07"
        izz="4.36287378114362E-05" />
    </inertial>
    <visual>
      <origin
        xyz="0 0 0"
        rpy="0 0 0" />
      <geometry>
        <mesh filename="package://spiderbotv8_description/meshes/base_link.STL" />
      </geometry>
      <material name="">
        <color rgba="0.752941176470588 0.752941176470588 0.752941176470588 1" />
      </material>
    </visual>
    <collision>
      <origin
        xyz="0 0 0"
        rpy="0 0 0" />
      <geometry>
        <mesh filename="package://spiderbotv8_description/meshes/base_link.STL" />
      </geometry>
    </collision>
  </link>
  <link
    name="r1">
    <inertial>
      <origin
        xyz="-0.020499999920902 0.000389285101961867 0.0198892805772913"
        rpy="0 0 0" />
      <mass
        value="0.00713023456386856" />
      <inertia
        ixx="7.56087099566393E-07"
        ixy="2.42840649896817E-09"
        ixz="-2.42840649896825E-09"
        iyy="5.95760525058341E-07"
        iyz="2.50084225320641E-09"
        izz="5.95760523642093E-07" />
    </inertial>
    <visual>
      <origin
        xyz="0 0 0"
        rpy="0 0 0" />
      <geometry>
        <mesh
          filename="package://spiderbotv8_description/meshes/r1.STL" />
      </geometry>
      <material
        name="">
        <color
          rgba="0.752941176470588 0.752941176470588 0.752941176470588 1" />
      </material>
    </visual>
    <collision>
      <origin
        xyz="0 0 0"
        rpy="0 0 0" />
      <geometry>
        <mesh
          filename="package://spiderbotv8_description/meshes/r1.STL" />
      </geometry>
    </collision>
  </link>
  <joint
    name="right1"
    type="revolute">
    <origin
      xyz="-0.030488 -0.027296 0.0193"
      rpy="0 0 0" />
    <parent
      link="base_link" />
    <child
      link="r1" />
    <axis
      xyz="0 0 -1" />
    <limit
      lower="-1.57"
      upper="1.57"
      effort="100"
      velocity="5" />
  </joint>
  <link
    name="sr1">
    <inertial>
      <origin
        xyz="-0.0103855500283455 0.0172280687962712 0.000907834339010391"
        rpy="0 0 0" />
      <mass
        value="0.0122153753102686" />
      <inertia
        ixx="6.06191507620996E-07"
        ixy="-2.6357706811751E-08"
        ixz="-4.62613535616074E-08"
        iyy="2.09883870458556E-06"
        iyz="-5.7703659796975E-16"
        izz="2.33635633104651E-06" />
    </inertial>
    <visual>
      <origin
        xyz="0 0 0"
        rpy="0 0 0" />
      <geometry>
        <mesh
          filename="package://spiderbotv8_description/meshes/sr1.STL" />
      </geometry>
      <material
        name="">
        <color
          rgba="0.752941176470588 0.752941176470588 0.752941176470588 1" />
      </material>
    </visual>
    <collision>
      <origin
        xyz="0 0 0"
        rpy="0 0 0" />
      <geometry>
        <mesh
          filename="package://spiderbotv8_description/meshes/sr1.STL" />
      </geometry>
    </collision>
  </link>
  <joint
    name="suppright1"
    type="revolute">
    <origin
      xyz="-0.041 -0.0195 0.0195"
      rpy="0 0 0" />
    <parent
      link="r1" />
    <child
      link="sr1" />
    <axis
      xyz="0 -1 0" />
    <limit
      lower="-1.57"
      upper="1.57"
      effort="100"
      velocity="5" />
  </joint>









<!-- left link front -->

  <link
    name="l1">
    <inertial>
      <origin
        xyz="-0.020499999920902 0.000389285101961867 0.0198892805772913"
        rpy="0 0 0" />
      <mass
        value="0.00713023456386856" />
      <inertia
        ixx="7.56087099566393E-07"
        ixy="2.42840649896817E-09"
        ixz="-2.42840649896825E-09"
        iyy="5.95760525058341E-07"
        iyz="2.50084225320641E-09"
        izz="5.95760523642093E-07" />
    </inertial>
    <visual>
      <origin
        xyz="0 0 0"
        rpy="0 0 0" />
      <geometry>
        <mesh
          filename="package://spiderbotv8_description/meshes/r1.STL" />
      </geometry>
      <material
        name="">
        <color
          rgba="0.752941176470588 0.752941176470588 0.752941176470588 1" />
      </material>
    </visual>
    <collision>
      <origin
        xyz="0 0 0"
        rpy="0 0 0" />
      <geometry>
        <mesh
          filename="package://spiderbotv8_description/meshes/r1.STL" />
      </geometry>
    </collision>
  </link>
  <joint
    name="left1"
    type="revolute">
    <origin
      xyz="0.030488 -0.027296 0.0193"
      rpy="0 0 3.1417" />
    <parent
      link="base_link" />
    <child
      link="l1" />
    <axis
      xyz="0 0 -1" />
    <limit
      lower="-1.57"
      upper="1.57"
      effort="100"
      velocity="5" />
  </joint>
  <link
    name="sl1">
    <inertial>
      <origin
        xyz="-0.0103855500283455 0.0172280687962712 0.000907834339010391"
        rpy="0 0 0" />
      <mass
        value="0.0122153753102686" />
      <inertia
        ixx="6.06191507620996E-07"
        ixy="-2.6357706811751E-08"
        ixz="-4.62613535616074E-08"
        iyy="2.09883870458556E-06"
        iyz="-5.7703659796975E-16"
        izz="2.33635633104651E-06" />
    </inertial>
    <visual>
      <origin
        xyz="0 0 0"
        rpy="0 0 0" />
      <geometry>
        <mesh
          filename="package://spiderbotv8_description/meshes/sr1.STL" />
      </geometry>
      <material
        name="">
        <color
          rgba="0.752941176470588 0.752941176470588 0.752941176470588 1" />
      </material>
    </visual>
    <collision>
      <origin
        xyz="0 0 0"
        rpy="0 0 0" />
      <geometry>
        <mesh
          filename="package://spiderbotv8_description/meshes/sr1.STL" />
      </geometry>
    </collision>
  </link>
  <joint
    name="suppleft1"
    type="revolute">
    <origin
      xyz="-0.041 -0.0195 0.0195"
      rpy="0 0 0" />
    <parent
      link="l1" />
    <child
      link="sl1" />
    <axis
      xyz="0 -1 0" />
    <limit
      lower="-1.57"
      upper="1.57"
      effort="100"
      velocity="5" />
  </joint>






    <link
    name="r2">
    <inertial>
      <origin
        xyz="-0.020499999920902 0.000389285101961867 0.0198892805772913"
        rpy="0 0 0" />
      <mass value="0.00713023456386856" />
      <inertia
        ixx="7.56087099566393E-07"
        ixy="2.42840649896817E-09"
        ixz="-2.42840649896825E-09"
        iyy="5.95760525058341E-07"
        iyz="2.50084225320641E-09"
        izz="5.95760523642093E-07" />
    </inertial>
    <visual>
      <origin
        xyz="0 0 0"
        rpy="0 0 0" />
      <geometry>
        <mesh filename="package://spiderbotv8_description/meshes/r1.STL" />
      </geometry>
      <material name="">
        <color rgba="0.752941176470588 0.752941176470588 0.752941176470588 1" />
      </material>
    </visual>
    <collision>
      <origin
        xyz="0 0 0"
        rpy="0 0 0" />
      <geometry>
        <mesh filename="package://spiderbotv8_description/meshes/r1.STL" />
      </geometry>
    </collision>
  </link>
  <joint
    name="right2"
    type="revolute">
    <origin
      xyz="-0.030488 0.027296 0.0193"
      rpy="0 0 0" />
    <parent
      link="base_link" />
    <child
      link="r2" />
    <axis
      xyz="0 0 -1" />
    <limit
      lower="-1.57"
      upper="1.57"
      effort="100"
      velocity="5" />
  </joint>
  <link
    name="sr2">
    <inertial>
      <origin
        xyz="-0.0103855500283455 0.0172280687962712 0.000907834339010391"
        rpy="0 0 0" />
      <mass
        value="0.0122153753102686" />
      <inertia
        ixx="6.06191507620996E-07"
        ixy="-2.6357706811751E-08"
        ixz="-4.62613535616074E-08"
        iyy="2.09883870458556E-06"
        iyz="-5.7703659796975E-16"
        izz="2.33635633104651E-06" />
    </inertial>
    <visual>
      <origin
        xyz="0 0 0"
        rpy="0 0 0" />
      <geometry>
        <mesh
          filename="package://spiderbotv8_description/meshes/sr1.STL" />
      </geometry>
      <material
        name="">
        <color
          rgba="0.752941176470588 0.752941176470588 0.752941176470588 1" />
      </material>
    </visual>
    <collision>
      <origin
        xyz="0 0 0"
        rpy="0 0 0" />
      <geometry>
        <mesh
          filename="package://spiderbotv8_description/meshes/sr1.STL" />
      </geometry>
    </collision>
  </link>
  <joint
    name="suppright2"
    type="revolute">
    <origin
      xyz="-0.041 -0.0195 0.0195"
      rpy="0 0 0" />
    <parent
      link="r2" />
    <child
      link="sr2" />
    <axis
      xyz="0 -1 0" />
    <limit
      lower="-1.57"
      upper="1.57"
      effort="100"
      velocity="5" />
  </joint>










<!-- back left -->
  <link
    name="l2">
    <inertial>
      <origin
        xyz="-0.020499999920902 0.000389285101961867 0.0198892805772913"
        rpy="0 0 0" />
      <mass
        value="0.00713023456386856" />
      <inertia
        ixx="7.56087099566393E-07"
        ixy="2.42840649896817E-09"
        ixz="-2.42840649896825E-09"
        iyy="5.95760525058341E-07"
        iyz="2.50084225320641E-09"
        izz="5.95760523642093E-07" />
    </inertial>
    <visual>
      <origin
        xyz="0 0 0"
        rpy="0 0 0" />
      <geometry>
        <mesh filename="package://spiderbotv8_description/meshes/r1.STL" />
      </geometry>
      <material name="">
        <color rgba="0.752941176470588 0.752941176470588 0.752941176470588 1" />
      </material>
    </visual>
    <collision>
      <origin
        xyz="0 0 0"
        rpy="0 0 0" />
      <geometry>
        <mesh filename="package://spiderbotv8_description/meshes/r1.STL" />
      </geometry>
    </collision>
  </link>
  <joint
    name="left2"
    type="revolute">
    <origin
      xyz="0.030488 0.027296 0.0193"
      rpy="0 0 3.1417" />
    <parent
      link="base_link" />
    <child
      link="l2" />
    <axis
      xyz="0 0 -1" />
    <limit
      lower="-1.57"
      upper="1.57"
      effort="100"
      velocity="5" />
  </joint>
  <link
    name="sl2">
    <inertial>
      <origin
        xyz="-0.0103855500283455 0.0172280687962712 0.000907834339010391"
        rpy="0 0 0" />
      <mass
        value="0.0122153753102686" />
      <inertia
        ixx="6.06191507620996E-07"
        ixy="-2.6357706811751E-08"
        ixz="-4.62613535616074E-08"
        iyy="2.09883870458556E-06"
        iyz="-5.7703659796975E-16"
        izz="2.33635633104651E-06" />
    </inertial>
    <visual>
      <origin
        xyz="0 0 0"
        rpy="0 0 0" />
      <geometry>
        <mesh
          filename="package://spiderbotv8_description/meshes/sr1.STL" />
      </geometry>
      <material
        name="">
        <color
          rgba="0.752941176470588 0.752941176470588 0.752941176470588 1" />
      </material>
    </visual>
    <collision>
      <origin
        xyz="0 0 0"
        rpy="0 0 0" />
      <geometry>
        <mesh
          filename="package://spiderbotv8_description/meshes/sr1.STL" />
      </geometry>
    </collision>
  </link>
  <joint
    name="suppleft2"
    type="revolute">
    <origin
      xyz="-0.041 -0.0195 0.0195"
      rpy="0 0 0" />
    <parent
      link="l2" />
    <child
      link="sl2" />
    <axis
      xyz="0 -1 0" />
    <limit
      lower="-1.57"
      upper="1.57"
      effort="100"
      velocity="5" />
  </joint>



<xacro:include filename="$(find spiderbotv8_description)/urdf/gazebo.xacro" />
<xacro:include filename="$(find spiderbotv8_description)/urdf/transmission.xacro" />
</robot>